<mujoco model="pendulum v1">
	<compiler inertiafromgeom="true"/>
	<default>
		<joint armature="0" damping="0" limited="true" />
		<!-- <geom contype="0" friction="1 0.1 0.1" rgba="0.7 0.7 0 1"/> -->
		<geom contype="0" rgba="0.7 0.7 0 1" friction="0 0 0" condim="1"/>
		<tendon/>
		<motor ctrlrange="-3 3"/>
	</default>
	<option gravity="0 0 -9.81" integrator="RK4" timestep="0.02"/>
	<size nstack="3000"/>
	<worldbody>
		<!-- <geom name="ground" type="plane" pos="0 0 0" size="40 40 40" /> -->
		<geom name="rail" pos="0 0 0" quat="0.707 0 0.707 0" rgba="0.3 0.3 0.7 1" size="0.02 20" type="capsule"/>
		<body name="cart" pos="0 0 0" >
			<joint axis="1 0 0" damping="1" limited="true" name="slider" pos="0 0 0" range="-1 1" type="slide" frictionloss="0"/>
			<geom name="cart" pos="0 0 0" quat="0.707 0 0.707 0" size="0.03 0.03 2" type="box" density="100"/>


			<body name="pole1" pos="-1.8 0 0" euler="0 -70 0">
				<joint axis="0 -1 0" name="hinge1" pos="0 0.5 0" range="-180 180" type="hinge"/>
				<geom pos="0 0 -0.15" name="cpole1" rgba="0 0.7 0.7 1" size="0.01 0.15" type="capsule" />
				<body name="toe1" pos="0 0 -0.15"/>
					<geom pos="0 0 -0.3" name="ball1" size="0.05" rgba="0.9 0 0 1" type="sphere" density="1000"/> <!--sphereのサイズは半径指定-->
			</body>

			<body name="pole2" pos="-1.35 0 0" euler="0 -30 0">
				<joint axis="0 -1 0" name="hinge2" pos="0 0.5 0" range="-180 180" type="hinge"/>
				<geom pos="0 0 -0.15" name="cpole2" rgba="0 0.7 0.7 1" size="0.01 0.15" type="capsule" />
				<body name="toe2" pos="0 0 -0.15"/>
					<geom pos="0 0 -.3" name="ball2" size="0.05 0.05" rgba="0.9 0 0 1" type="sphere" density="1000"/>
			</body>

			<body name="pole3" pos="-.9 0 0" euler="0 30 0">
				<joint axis="0 -1 0" name="hinge3" pos="0 0.5 0" range="-180 180" type="hinge"/>
				<geom pos="0 0 -0.15" name="cpole3" rgba="0 0.7 0.7 1" size="0.01 0.15" type="capsule" />
				<body name="toe3" pos="0 0 -0.15"/>
					<geom pos="0 0 -.3" name="ball3" size="0.05 0.05" rgba="0.9 0 0 1" type="sphere" density="1000"/>
			</body>

			<body name="pole4" pos="-.45 0 0" euler="0 20 0">
				<joint axis="0 -1 0" name="hinge4" pos="0 0.5 0" range="-180 180" type="hinge"/>
				<geom pos="0 0 -0.15" name="cpole4" rgba="0 0.7 0.7 1" size="0.01 0.15" type="capsule" />
				<body name="toe4" pos="0 0 -0.15"/>
					<geom pos="0 0 -0.3" name="ball4" size="0.05" rgba="0.9 0 0 1" type="sphere" density="1000"/> <!--sphereのサイズは半径指定-->
			</body>

			<body name="pole5" pos="0 0 0" euler="0 -60 0">
				<joint axis="0 -1 0" name="hinge5" pos="0 0.5 0" range="-180 180" type="hinge"/>
				<geom pos="0 0 -0.15" name="cpole5" rgba="0 0.7 0.7 1" size="0.01 0.15" type="capsule" />
				<body name="toe5" pos="0 0 -0.15"/>
					<geom pos="0 0 -.3" name="ball5" size="0.05 0.05" rgba="0.9 0 0 1" type="sphere" density="1000"/>
			</body>

			<body name="pole6" pos="0.45 0 0" euler="0 50 0">
				<joint axis="0 -1 0" name="hinge6" pos="0 0.5 0" range="-180 180" type="hinge"/>
				<geom pos="0 0 -0.15" name="cpole6" rgba="0 0.7 0.7 1" size="0.01 0.15" type="capsule" />
				<body name="toe6" pos="0 0 -0.15"/>
					<geom pos="0 0 -.3" name="ball6" size="0.05 0.05" rgba="0.9 0 0 1" type="sphere" density="1000"/>
			</body>

			<body name="pole7" pos=".9 0 0" euler="0 -10 0">
				<joint axis="0 -1 0" name="hinge7" pos="0 0.5 0" range="-180 180" type="hinge"/>
				<geom pos="0 0 -0.15" name="cpole7" rgba="0 0.7 0.7 1" size="0.01 0.15" type="capsule" />
				<body name="toe7" pos="0 0 -0.15"/>
					<geom pos="0 0 -0.3" name="ball7" size="0.05" rgba="0.9 0 0 1" type="sphere" density="1000"/> <!--sphereのサイズは半径指定-->
			</body>

			<body name="pole8" pos="1.35 0 0" euler="0 0 0">
				<joint axis="0 -1 0" name="hinge8" pos="0 0.5 0" range="-180 180" type="hinge"/>
				<geom pos="0 0 -0.15" name="cpole8" rgba="0 0.7 0.7 1" size="0.01 0.15" type="capsule" />
				<body name="toe8" pos="0 0 -0.15"/>
					<geom pos="0 0 -.3" name="ball8" size="0.05 0.05" rgba="0.9 0 0 1" type="sphere" density="1000"/>
			</body>

			<body name="pole9" pos="1.8 0 0" euler="0 45 0">
				<joint axis="0 -1 0" name="hinge9" pos="0 0.5 0" range="-180 180" type="hinge"/>
				<geom pos="0 0 -0.15" name="cpole9" rgba="0 0.7 0.7 1" size="0.01 0.15" type="capsule" />
				<body name="toe9" pos="0 0 -0.15"/>
					<geom pos="0 0 -.3" name="ball9" size="0.05 0.05" rgba="0.9 0 0 1" type="sphere" density="1000"/>
			</body>

			<!-- <body name="pole10" pos="0.75 0 0" euler="0 30 0">
				<joint axis="0 -1 0" name="hinge10" pos="0 0.5 0" range="-120 120" type="hinge"/>
				<geom pos="0 0 -0.15" name="cpole10" rgba="0 0.7 0.7 1" size="0.01 0.15" type="capsule" />
				<body name="toe10" pos="0 0 -0.15"/>
					<geom pos="0 0 -.3" name="ball10" size="0.05 0.05" rgba="0.9 0 0 1" type="sphere" density="1000"/>
			</body> -->


		</body>
	</worldbody>
	<actuator>
		<motor gear="1000" joint="slider" name="slide"/>
	</actuator>
</mujoco>